Workbook

Sheet Read me
A1: AIVOA Deviation Intake: field registry
A2: Generated 2026-09-27 09:57 from app/fields.py (single source of truth).
A4: How to use
A5: • Fields: one row per field, filterable. Tier colours: blue = from the report, purple = calculated, green = set by a person.
A6: • Owner and Notes (yellow columns) are for people to fill in. They are kept when the sheet is regenerated.
A7: • Every other column comes from the code. Change fields in backend/app/fields.py, then regenerate; do not edit them here.
A8: • Sections, Tiers: counts are live formulas over the Fields sheet.
A9: • Rules: how the calculated fields are worked out.
A11: Regenerate
A12: cd backend → .venv\Scripts\python scripts\export_field_registry.py
A13: or ask the Claude Code agent: field-registry-sheet

Sheet Fields
A1: # | B1: Field key | C1: Screen label (plain) | D1: Regulatory label | E1: Section | F1: Tier | G1: Filled by | H1: Type | I1: Allowed options | J1: Change by chat? | K1: Re-checks risk? | L1: Description / help | M1: Chat wording | N1: Owner | O1: Notes
A2: 1 | B2: title | C2: Title | D2: Deviation Title | E2: 1. Event Details | F2: A · AI-extracted | G2: From the report | H2: textarea | J2: Yes | K2: No | L2: One-line summary of the event. | M2: title
A3: 2 | B3: date_detected | C3: Date found | D3: Date Detected | E3: 1. Event Details | F3: A · AI-extracted | G3: From the report | H3: date | J3: Yes | K3: No | M3: date found
A4: 3 | B4: reported_by | C4: Reported By | D4: Reported By | E4: 1. Event Details | F4: A · AI-extracted | G4: From the report | H4: text | J4: Yes | K4: No | M4: reported by
A5: 4 | B5: department | C5: Department | D5: Department | E5: 1. Event Details | F5: A · AI-extracted | G5: From the report | H5: text | J5: Yes | K5: No | M5: department
A6: 5 | B6: area_location | C6: Area / location | D6: Area / Location | E6: 1. Event Details | F6: A · AI-extracted | G6: From the report | H6: text | J6: Yes | K6: No | M6: area / location
A7: 6 | B7: site | C7: Site | D7: Site | E7: 1. Event Details | F7: C · Human/System | G7: Set by a person | H7: text | J7: Yes | K7: No | L7: Defaults from server config. | M7: site
A8: 7 | B8: product_name | C8: Product Name | D8: Product Name | E8: 2. Product & Process | F8: A · AI-extracted | G8: From the report | H8: text | J8: Yes | K8: No | M8: product name
A9: 8 | B9: batch_number | C9: Batch / Lot Number | D9: Batch / Lot Number | E9: 2. Product & Process | F9: A · AI-extracted | G9: From the report | H9: text | J9: Yes | K9: No | M9: batch number
A10: 9 | B10: manufacturing_stage | C10: Production step | D10: Manufacturing Stage | E10: 2. Product & Process | F10: A · AI-extracted | G10: From the report | H10: select | I10: Raw Material Dispensing | Reaction | Crystallization | Filtration / Centrifugation | Drying | Milling / Sieving | Blending | Packaging | Other | J10: Yes | K10: Yes | M10: production step
A11: 10 | B11: equipment_id | C11: Machine / equipment ID | D11: Equipment ID | E11: 2. Product & Process | F11: A · AI-extracted | G11: From the report | H11: text | J11: Yes | K11: No | M11: machine / equipment ID
A12: 11 | B12: process_parameter | C12: What was measured | D12: Process Parameter | E12: 2. Product & Process | F12: A · AI-extracted | G12: From the report | H12: text | J12: Yes | K12: Yes | M12: what was measured
A13: 12 | B13: approved_range | C13: Allowed range | D13: Approved Range | E13: 2. Product & Process | F13: A · AI-extracted | G13: From the report | H13: text | J13: Yes | K13: Yes | L13: e.g. 60-65 °C, NMT 0.5%, NLT 98%, 2.0 ± 0.2 | M13: allowed range
A14: 13 | B14: observed_value | C14: Actual value | D14: Observed Value | E14: 2. Product & Process | F14: A · AI-extracted | G14: From the report | H14: text | J14: Yes | K14: Yes | M14: actual value
A15: 14 | B15: description | C15: What happened | D15: Deviation Description | E15: 3. Description & Actions | F15: A · AI-extracted | G15: From the report | H15: textarea | J15: Yes | K15: Yes | L15: Clean QMS narrative: what, where, when, how detected. | M15: description of what happened
A16: 15 | B16: immediate_action | C16: Immediate action taken | D16: Immediate Action / Containment | E16: 3. Description & Actions | F16: A · AI-extracted | G16: From the report | H16: textarea | J16: Yes | K16: No | M16: immediate action taken
A17: 16 | B17: root_cause_hypothesis | C17: Likely cause | D17: Root Cause Hypothesis | E17: 3. Description & Actions | F17: A · AI-extracted | G17: From the report | H17: textarea | J17: Yes | K17: No | L17: Only if the source states a suspected cause. | M17: likely cause
A18: 17 | B18: batch_disposition | C18: What happens to the batch | D18: Batch Disposition | E18: 3. Description & Actions | F18: A · AI-extracted | G18: From the report | H18: select | I18: Quarantined / On Hold | Under Evaluation | Released | Reprocess / Rework | Rejected | J18: Yes | K18: No | M18: what happens to the batch
A19: 18 | B19: deviation_type | C19: Planned or unplanned | D19: Deviation Type | E19: 4. Classification | F19: A · AI-extracted | G19: From the report | H19: select | I19: Planned | Unplanned | J19: Yes | K19: No | M19: planned or unplanned
A20: 19 | B20: category | C20: Category | D20: Category | E20: 4. Classification | F20: A · AI-extracted | G20: From the report | H20: select | I20: Process Parameter Excursion | Equipment Malfunction | Material / Specification (OOS) | Documentation | Environmental Monitoring | Utility Failure | Cleaning | Other | J20: Yes | K20: Yes | M20: category
A21: 20 | B21: gmp_impact | C21: Affects product quality? (GMP) | D21: GMP Impact | E21: 4. Classification | F21: A · AI-extracted | G21: From the report | H21: select | I21: Yes | No | Potential | J21: Yes | K21: Yes | M21: effect on product quality (GMP impact)
A22: 21 | B22: root_cause_category | C22: Type of cause | D22: Root Cause Category | E22: 4. Classification | F22: A · AI-extracted | G22: From the report | H22: select | I22: Equipment | Process | Material | Human Error | Method / Procedure | Environment | Utility | Under Investigation | J22: Yes | K22: No | M22: type of cause
A23: 22 | B23: deviation_id | C23: Record number | D23: Deviation ID | E23: 5. Administration | F23: C · Human/System | G23: Set by a person | H23: text | J23: No | K23: No | L23: Auto-generated on save (DEV-YYYY-NNNN). | M23: record number
A24: 23 | B24: status | C24: Status | D24: Status | E24: 5. Administration | F24: C · Human/System | G24: Set by a person | H24: select | I24: Draft | Open | Under Investigation | Pending QA Approval | Closed | J24: Yes | K24: No | M24: status
A25: 24 | B25: date_reported | C25: Date recorded | D25: Date Reported | E25: 5. Administration | F25: C · Human/System | G25: Set by a person | H25: date | J25: No | K25: No | L25: System date when the deviation was logged. | M25: date recorded
A26: 25 | B26: assigned_investigator | C26: Investigator | D26: Assigned Investigator | E26: 5. Administration | F26: C · Human/System | G26: Set by a person | H26: text | J26: Yes | K26: No | M26: investigator
A27: 26 | B27: ha_notification_required | C27: Tell the health authority? | D27: HA Notification Required | E27: 5. Administration | F27: C · Human/System | G27: Set by a person | H27: select | I27: Yes | No | To be evaluated | J27: Yes | K27: No | M27: whether to tell the health authority
A28: 27 | B28: customer_notification_required | C28: Tell the customer? | D28: Customer Notification Required | E28: 5. Administration | F28: C · Human/System | G28: Set by a person | H28: select | I28: Yes | No | To be evaluated | J28: Yes | K28: No | M28: whether to tell the customer
A29: 28 | B29: quarantine_reference | C29: Hold / quarantine number | D29: Quarantine Reference | E29: 5. Administration | F29: C · Human/System | G29: Set by a person | H29: text | J29: Yes | K29: No | M29: hold / quarantine number
A30: 29 | B30: source_document | C30: Received from | D30: Source Document | E30: 5. Administration | F30: C · Human/System | G30: Set by a person | H30: text | J30: No | K30: No | M30: source
A31: 30 | B31: last_updated_by | C31: Last changed by | D31: Last Updated By | E31: 5. Administration | F31: C · Human/System | G31: Set by a person | H31: text | J31: Yes | K31: No | M31: last changed by
A32: 31 | B32: severity_score | C32: Severity | D32: Severity (S) | E32: Risk Assessment | F32: B · AI-computed | G32: Calculated | H32: score | J32: Yes | K32: No | M32: severity score
A33: 32 | B33: occurrence_score | C33: Likelihood | D33: Occurrence (O) | E33: Risk Assessment | F33: B · AI-computed | G33: Calculated | H33: score | J33: Yes | K33: No | M33: likelihood score
A34: 33 | B34: detectability_score | C34: Hard to detect | D34: Detectability (D) | E34: Risk Assessment | F34: B · AI-computed | G34: Calculated | H34: score | J34: Yes | K34: No | M34: hard-to-detect score
A35: 34 | B35: rpn | C35: Risk score (RPN) | D35: RPN (S×O×D) | E35: Risk Assessment | F35: B · AI-computed | G35: Calculated | H35: text | J35: No | K35: No | M35: risk score (RPN)
A36: 35 | B36: severity_classification | C36: Severity level | D36: Severity (Suggested) | E36: Risk Assessment | F36: B · AI-computed | G36: Calculated | H36: select | I36: Critical | Major | Minor | J36: Yes | K36: No | L36: Rule-derived from S and RPN unless explicitly overridden by the user. | M36: severity level
A37: 36 | B37: severity_reasoning | C37: Why this risk level | D37: Initial Risk Assessment | E37: Risk Assessment | F37: B · AI-computed | G37: Calculated | H37: textarea | J37: Yes | K37: No | M37: reason for the risk level
A38: 37 | B38: impact_assessment | C38: Possible impact | D38: Impact Assessment | E38: Risk Assessment | F38: B · AI-computed | G38: Calculated | H38: textarea | J38: Yes | K38: No | M38: possible impact
A39: 38 | B39: suggested_next_action | C39: Suggested next step | D39: Suggested Next Action | E39: Risk Assessment | F39: B · AI-computed | G39: Calculated | H39: text | J39: Yes | K39: No | L39: e.g. Quarantine batch and route to QA investigation. | M39: suggested next step
A40: 39 | B40: capa_required | C40: Corrective action (CAPA) | D40: CAPA Required | E40: Risk Assessment | F40: B · AI-computed | G40: Calculated | H40: select | I40: Yes | No | J40: Yes | K40: No | M40: corrective action (CAPA)
...

Sheet Sections
A1: Section | B1: Fields | C1: From the report (A) | D1: Calculated (B) | E1: Set by a person (C) | F1: Change by chat
A2: 1. Event Details | B2: =COUNTIF(Fields!$E$2:$E$45,A2) | C2: =COUNTIFS(Fields!$E$2:$E$45,A2,Fields!$F$2:$F$45,"A*") | D2: =COUNTIFS(Fields!$E$2:$E$45,A2,Fields!$F$2:$F$45,"B*") | E2: =COUNTIFS(Fields!$E$2:$E$45,A2,Fields!$F$2:$F$45,"C*") | F2: =COUNTIFS(Fields!$E$2:$E$45,A2,Fields!$J$2:$J$45,"Yes")
A3: 2. Product & Process | B3: =COUNTIF(Fields!$E$2:$E$45,A3) | C3: =COUNTIFS(Fields!$E$2:$E$45,A3,Fields!$F$2:$F$45,"A*") | D3: =COUNTIFS(Fields!$E$2:$E$45,A3,Fields!$F$2:$F$45,"B*") | E3: =COUNTIFS(Fields!$E$2:$E$45,A3,Fields!$F$2:$F$45,"C*") | F3: =COUNTIFS(Fields!$E$2:$E$45,A3,Fields!$J$2:$J$45,"Yes")
A4: 3. Description & Actions | B4: =COUNTIF(Fields!$E$2:$E$45,A4) | C4: =COUNTIFS(Fields!$E$2:$E$45,A4,Fields!$F$2:$F$45,"A*") | D4: =COUNTIFS(Fields!$E$2:$E$45,A4,Fields!$F$2:$F$45,"B*") | E4: =COUNTIFS(Fields!$E$2:$E$45,A4,Fields!$F$2:$F$45,"C*") | F4: =COUNTIFS(Fields!$E$2:$E$45,A4,Fields!$J$2:$J$45,"Yes")
A5: 4. Classification | B5: =COUNTIF(Fields!$E$2:$E$45,A5) | C5: =COUNTIFS(Fields!$E$2:$E$45,A5,Fields!$F$2:$F$45,"A*") | D5: =COUNTIFS(Fields!$E$2:$E$45,A5,Fields!$F$2:$F$45,"B*") | E5: =COUNTIFS(Fields!$E$2:$E$45,A5,Fields!$F$2:$F$45,"C*") | F5: =COUNTIFS(Fields!$E$2:$E$45,A5,Fields!$J$2:$J$45,"Yes")
A6: 5. Administration | B6: =COUNTIF(Fields!$E$2:$E$45,A6) | C6: =COUNTIFS(Fields!$E$2:$E$45,A6,Fields!$F$2:$F$45,"A*") | D6: =COUNTIFS(Fields!$E$2:$E$45,A6,Fields!$F$2:$F$45,"B*") | E6: =COUNTIFS(Fields!$E$2:$E$45,A6,Fields!$F$2:$F$45,"C*") | F6: =COUNTIFS(Fields!$E$2:$E$45,A6,Fields!$J$2:$J$45,"Yes")
A7: Risk Assessment | B7: =COUNTIF(Fields!$E$2:$E$45,A7) | C7: =COUNTIFS(Fields!$E$2:$E$45,A7,Fields!$F$2:$F$45,"A*") | D7: =COUNTIFS(Fields!$E$2:$E$45,A7,Fields!$F$2:$F$45,"B*") | E7: =COUNTIFS(Fields!$E$2:$E$45,A7,Fields!$F$2:$F$45,"C*") | F7: =COUNTIFS(Fields!$E$2:$E$45,A7,Fields!$J$2:$J$45,"Yes")
A8: Total | B8: =SUM(B2:B7) | C8: =SUM(C2:C7) | D8: =SUM(D2:D7) | E8: =SUM(E2:E7) | F8: =SUM(F2:F7)

Sheet Tiers
A1: Tier | B1: Name on screen | C1: Who fills it | D1: Fields
A2: A · AI-extracted | B2: From the report | C2: The AI fills it ONLY with facts written in the source report; left blank if absent. | D2: =COUNTIF(Fields!$F$2:$F$45,"A*")
A3: B · AI-computed | B3: Calculated | C3: The AI risk check (scores, reasoning) or fixed Python rules (RPN, class, CAPA, deadline). | D3: =COUNTIF(Fields!$F$2:$F$45,"B*")
A4: C · Human/System | B4: Set by a person | C4: Set by the system or by an explicit user instruction. The AI never invents it. | D4: =COUNTIF(Fields!$F$2:$F$45,"C*")

Sheet Rules
A1: Rule | B1: Definition | C1: Source
A2: Risk score (RPN) | B2: Severity × Likelihood (occurrence) × Hard to detect (detectability); each 1-5, so 1-125. | C2: app/rules.py
A3: Severity level: Critical | B3: Severity 5, or RPN 100 or more (unless a person overrides it with a reason). | C3: app/rules.py classify_severity
A4: Severity level: Major | B4: Severity 3 or more, or RPN 40 or more. | C4: app/rules.py classify_severity
A5: Severity level: Minor | B5: Otherwise. | C5: app/rules.py classify_severity
A6: Corrective action (CAPA) needed | B6: Critical or Major, or RPN 60 or more. A person may override with a reason. | C6: app/rules.py
A7: Investigation deadline | B7: Date found + Critical 15 days, Major 30 days, Minor 45 days. | C7: app/rules.py DUE_DAYS
A8: How far outside the limit | B8: Parsed from allowed range vs actual value, e.g. '+6 °C above upper limit 65 °C (9.2% over)'. | C8: app/rules.py
A9: Happened before? | B9: Earlier record on the same machine, or same product + measurement (database lookup). | C9: app/crud.py find_related
A10: Record number | B10: DEV-YYYY-NNNN, restarts each year, never reused after a deletion. | C10: app/crud.py next_deviation_id
